{
 "cells": [
  {
   "cell_type": "code",
   "execution_count": 253,
   "metadata": {},
   "outputs": [],
   "source": [
    "import os\n",
    "from zipfile import is_zipfile, ZipFile\n",
    "from pickle import load, dump\n",
    "import matplotlib.pyplot as plt\n",
    "from numpy import array, stack, zeros\n",
    "import torch \n",
    "from torch.utils.data import Dataset, DataLoader, random_split\n",
    "from torch import nn \n",
    "from torch import optim \n",
    "# from torchsummary import summary"
   ]
  },
  {
   "cell_type": "markdown",
   "metadata": {
    "pycharm": {
     "name": "#%% md\n"
    }
   },
   "source": [
    "## Unzip precoder dataset"
   ]
  },
  {
   "cell_type": "code",
   "execution_count": 254,
   "metadata": {
    "collapsed": false,
    "jupyter": {
     "outputs_hidden": false
    },
    "pycharm": {
     "name": "#%%\n"
    }
   },
   "outputs": [
    {
     "name": "stdout",
     "output_type": "stream",
     "text": [
      "datasets.zip was not found.\n"
     ]
    }
   ],
   "source": [
    "dir_name = 'datasets'\n",
    "if os.path.exists(dir_name):\n",
    "    print(\"Data has already been unzipped.\")\n",
    "else:\n",
    "    if os.path.exists(f'{dir_name}.zip'):\n",
    "        if is_zipfile(f'{dir_name}.zip'):\n",
    "            with ZipFile(f'{dir_name}.zip', 'r') as zip_data_obj:\n",
    "                zip_data_obj.extractall()\n",
    "        else:\n",
    "            print('File exists, but is not a zip archive.')\n",
    "    else:\n",
    "        print('datasets.zip was not found.')\n",
    "\n"
   ]
  },
  {
   "cell_type": "markdown",
   "metadata": {},
   "source": [
    "## Load precoder dataset"
   ]
  },
  {
   "cell_type": "code",
   "execution_count": 255,
   "metadata": {},
   "outputs": [],
   "source": [
    "def load_dataset(dir_name, fading, num_ant, SNR_dB, bit_codebook):\n",
    "\n",
    "    if not os.path.exists(dir_name):\n",
    "        os.makedirs(dir_name)\n",
    "    file_name = f'{dir_name}/{fading}_precoder_data_{num_ant}_ant_SNR_{SNR_dB}dB_{bit_codebook}_bit_codebk'\n",
    "    print(file_name)\n",
    "    with open(f'{file_name}.pkl', 'rb') as f:\n",
    "        precoders, labels = load(f)\n",
    "    return precoders, labels"
   ]
  },
  {
   "cell_type": "markdown",
   "metadata": {},
   "source": [
    "## Visualization of Data"
   ]
  },
  {
   "cell_type": "code",
   "execution_count": 256,
   "metadata": {},
   "outputs": [],
   "source": [
    "def visualize(precoders):\n",
    "    # test plots\n",
    "    for i in range(2):\n",
    "        plt.scatter(precoders[i][0::2], precoders[i][1::2])\n",
    "        plt.show()"
   ]
  },
  {
   "cell_type": "markdown",
   "metadata": {},
   "source": [
    "## Precoder dataset class that packages the dataset into a format compatible with PyTorch"
   ]
  },
  {
   "cell_type": "code",
   "execution_count": 257,
   "metadata": {},
   "outputs": [],
   "source": [
    "class PrecoderDataset(Dataset):\n",
    "    def __init__(self, data, target, transform=None):\n",
    "        self.data = torch.from_numpy(data).float()\n",
    "        self.target = torch.from_numpy(target).long()\n",
    "        self.transform = transform\n",
    "        \n",
    "    def __getitem__(self, index):\n",
    "        x = self.data[index]\n",
    "        y = self.target[index]\n",
    "        \n",
    "        if self.transform:\n",
    "            x = self.transform(x)\n",
    "        return x, y\n",
    "    \n",
    "    def __len__(self):\n",
    "        return len(self.data)"
   ]
  },
  {
   "cell_type": "markdown",
   "metadata": {},
   "source": [
    "## Neural Network Class"
   ]
  },
  {
   "cell_type": "code",
   "execution_count": 258,
   "metadata": {},
   "outputs": [],
   "source": [
    "\n",
    "class Model(torch.nn.Module):\n",
    "    def __init__(self, input_size, output_size):\n",
    "        super(Model, self).__init__()\n",
    "        # define layers and activation function as class parameters\n",
    "        self.fc1 = nn.Linear(in_features=input_size, out_features=100)\n",
    "        self.fc2 = nn.Linear(in_features=100, out_features=100)\n",
    "        self.output = nn.Linear(in_features=100, out_features=output_size)\n",
    "        self.relu = torch.nn.ReLU()\n",
    "        self.softmax = torch.nn.Softmax()\n",
    "\n",
    "    def forward(self, x):\n",
    "        # define NN connections here, output of last layer is pred\n",
    "        x = self.relu(self.fc1(x))\n",
    "        x = self.relu(self.fc2(x))\n",
    "        pred = self.softmax(self.output(x))\n",
    "        return pred\n"
   ]
  },
  {
   "cell_type": "markdown",
   "metadata": {},
   "source": [
    "## Essential System Parameters"
   ]
  },
  {
   "cell_type": "code",
   "execution_count": 259,
   "metadata": {},
   "outputs": [],
   "source": [
    "max_iter = 100000\n",
    "fading = 1\n",
    "num_ant = 2\n",
    "SNR_dB = 20\n",
    "bit_codebook = 1\n",
    "visual = 0"
   ]
  },
  {
   "cell_type": "markdown",
   "metadata": {},
   "source": [
    "## Training Parameters"
   ]
  },
  {
   "cell_type": "code",
   "execution_count": 260,
   "metadata": {},
   "outputs": [],
   "source": [
    "learning_rate = 0.01\n",
    "num_epochs = 100 # Number of times you go through the whole dataset"
   ]
  },
  {
   "cell_type": "markdown",
   "metadata": {
    "pycharm": {
     "name": "#%% md\n"
    }
   },
   "source": [
    "## Simulation iterations\n",
    "1. Load dataset\n",
    "2. Visualize, if necessary \n",
    "3. Create instance of precoder dataset class (Package dataset such that it is compatible for PyTorch)\n",
    "4. Split dataset into 80% training and 20% validation\n",
    "5. Create PyTorch dataloaders for training and validation data (Dataloaders divide the dataset into chuncks called batches. We can pass data to the neural network one batch at a time) \n",
    "6. Create an instance of neural network class\n",
    "7. Define the loss and optimizer\n",
    "8. Epoch - one pass of the entire dataset (training + validation)\n",
    "9. In each epoch you iterate over several batches (Batch - chunk of data that is fed to the neural network in one go) "
   ]
  },
  {
   "cell_type": "code",
   "execution_count": null,
   "metadata": {
    "collapsed": false,
    "jupyter": {
     "outputs_hidden": false
    },
    "pycharm": {
     "name": "#%%\n"
    }
   },
   "outputs": [
    {
     "name": "stderr",
     "output_type": "stream",
     "text": [
      "ERROR:root:Internal Python error in the inspect module.\n",
      "Below is the traceback from this internal error.\n",
      "\n",
      "ERROR:root:Internal Python error in the inspect module.\n",
      "Below is the traceback from this internal error.\n",
      "\n",
      "ERROR:root:Internal Python error in the inspect module.\n",
      "Below is the traceback from this internal error.\n",
      "\n"
     ]
    },
    {
     "name": "stdout",
     "output_type": "stream",
     "text": [
      "Traceback (most recent call last):\n",
      "  File \"/home/utsa/anaconda3/envs/py37/lib/python3.7/site-packages/IPython/core/interactiveshell.py\", line 3418, in run_code\n",
      "    exec(code_obj, self.user_global_ns, self.user_ns)\n",
      "  File \"<ipython-input-261-55ddc41a7a3a>\", line 1, in <module>\n",
      "    precoders, labels = load_dataset('datasets', fading, ant, SNR, bit)\n",
      "  File \"<ipython-input-255-529c16c6c308>\", line 4, in load_dataset\n",
      "    os.makedirs(dir_name)\n",
      "  File \"/home/utsa/anaconda3/envs/py37/lib/python3.7/os.py\", line 223, in makedirs\n",
      "    mkdir(name, mode)\n",
      "FileNotFoundError: [Errno 2] No such file or directory: 'datasets'\n",
      "\n",
      "During handling of the above exception, another exception occurred:\n",
      "\n",
      "Traceback (most recent call last):\n",
      "  File \"/home/utsa/anaconda3/envs/py37/lib/python3.7/site-packages/IPython/core/interactiveshell.py\", line 2045, in showtraceback\n",
      "    stb = value._render_traceback_()\n",
      "AttributeError: 'FileNotFoundError' object has no attribute '_render_traceback_'\n",
      "\n",
      "During handling of the above exception, another exception occurred:\n",
      "\n",
      "Traceback (most recent call last):\n",
      "  File \"/home/utsa/anaconda3/envs/py37/lib/python3.7/site-packages/IPython/core/ultratb.py\", line 1170, in get_records\n",
      "    return _fixed_getinnerframes(etb, number_of_lines_of_context, tb_offset)\n",
      "  File \"/home/utsa/anaconda3/envs/py37/lib/python3.7/site-packages/IPython/core/ultratb.py\", line 316, in wrapped\n",
      "    return f(*args, **kwargs)\n",
      "  File \"/home/utsa/anaconda3/envs/py37/lib/python3.7/site-packages/IPython/core/ultratb.py\", line 350, in _fixed_getinnerframes\n",
      "    records = fix_frame_records_filenames(inspect.getinnerframes(etb, context))\n",
      "  File \"/home/utsa/anaconda3/envs/py37/lib/python3.7/inspect.py\", line 1502, in getinnerframes\n",
      "    frameinfo = (tb.tb_frame,) + getframeinfo(tb, context)\n",
      "  File \"/home/utsa/anaconda3/envs/py37/lib/python3.7/inspect.py\", line 1460, in getframeinfo\n",
      "    filename = getsourcefile(frame) or getfile(frame)\n",
      "  File \"/home/utsa/anaconda3/envs/py37/lib/python3.7/inspect.py\", line 696, in getsourcefile\n",
      "    if getattr(getmodule(object, filename), '__loader__', None) is not None:\n",
      "  File \"/home/utsa/anaconda3/envs/py37/lib/python3.7/inspect.py\", line 725, in getmodule\n",
      "    file = getabsfile(object, _filename)\n",
      "  File \"/home/utsa/anaconda3/envs/py37/lib/python3.7/inspect.py\", line 709, in getabsfile\n",
      "    return os.path.normcase(os.path.abspath(_filename))\n",
      "  File \"/home/utsa/anaconda3/envs/py37/lib/python3.7/posixpath.py\", line 383, in abspath\n",
      "    cwd = os.getcwd()\n",
      "FileNotFoundError: [Errno 2] No such file or directory\n",
      "Traceback (most recent call last):\n",
      "  File \"/home/utsa/anaconda3/envs/py37/lib/python3.7/site-packages/IPython/core/interactiveshell.py\", line 3418, in run_code\n",
      "    exec(code_obj, self.user_global_ns, self.user_ns)\n",
      "  File \"<ipython-input-261-55ddc41a7a3a>\", line 1, in <module>\n",
      "    precoders, labels = load_dataset('datasets', fading, ant, SNR, bit)\n",
      "  File \"<ipython-input-255-529c16c6c308>\", line 4, in load_dataset\n",
      "    os.makedirs(dir_name)\n",
      "  File \"/home/utsa/anaconda3/envs/py37/lib/python3.7/os.py\", line 223, in makedirs\n",
      "    mkdir(name, mode)\n",
      "FileNotFoundError: [Errno 2] No such file or directory: 'datasets'\n",
      "\n",
      "During handling of the above exception, another exception occurred:\n",
      "\n",
      "Traceback (most recent call last):\n",
      "  File \"/home/utsa/anaconda3/envs/py37/lib/python3.7/site-packages/IPython/core/interactiveshell.py\", line 2045, in showtraceback\n",
      "    stb = value._render_traceback_()\n",
      "AttributeError: 'FileNotFoundError' object has no attribute '_render_traceback_'\n",
      "\n",
      "During handling of the above exception, another exception occurred:\n",
      "\n",
      "Traceback (most recent call last):\n",
      "  File \"/home/utsa/anaconda3/envs/py37/lib/python3.7/site-packages/IPython/core/interactiveshell.py\", line 3338, in run_ast_nodes\n",
      "    if (await self.run_code(code, result,  async_=asy)):\n",
      "  File \"/home/utsa/anaconda3/envs/py37/lib/python3.7/site-packages/IPython/core/interactiveshell.py\", line 3435, in run_code\n",
      "    self.showtraceback(running_compiled_code=True)\n",
      "  File \"/home/utsa/anaconda3/envs/py37/lib/python3.7/site-packages/IPython/core/interactiveshell.py\", line 2048, in showtraceback\n",
      "    value, tb, tb_offset=tb_offset)\n",
      "  File \"/home/utsa/anaconda3/envs/py37/lib/python3.7/site-packages/IPython/core/ultratb.py\", line 1437, in structured_traceback\n",
      "    self, etype, value, tb, tb_offset, number_of_lines_of_context)\n",
      "  File \"/home/utsa/anaconda3/envs/py37/lib/python3.7/site-packages/IPython/core/ultratb.py\", line 1337, in structured_traceback\n",
      "    self, etype, value, tb, tb_offset, number_of_lines_of_context\n",
      "  File \"/home/utsa/anaconda3/envs/py37/lib/python3.7/site-packages/IPython/core/ultratb.py\", line 1194, in structured_traceback\n",
      "    tb_offset)\n",
      "  File \"/home/utsa/anaconda3/envs/py37/lib/python3.7/site-packages/IPython/core/ultratb.py\", line 1151, in format_exception_as_a_whole\n",
      "    last_unique, recursion_repeat = find_recursion(orig_etype, evalue, records)\n",
      "  File \"/home/utsa/anaconda3/envs/py37/lib/python3.7/site-packages/IPython/core/ultratb.py\", line 451, in find_recursion\n",
      "    return len(records), 0\n",
      "TypeError: object of type 'NoneType' has no len()\n",
      "\n",
      "During handling of the above exception, another exception occurred:\n",
      "\n",
      "Traceback (most recent call last):\n",
      "  File \"/home/utsa/anaconda3/envs/py37/lib/python3.7/site-packages/IPython/core/interactiveshell.py\", line 2045, in showtraceback\n",
      "    stb = value._render_traceback_()\n",
      "AttributeError: 'TypeError' object has no attribute '_render_traceback_'\n",
      "\n",
      "During handling of the above exception, another exception occurred:\n",
      "\n",
      "Traceback (most recent call last):\n",
      "  File \"/home/utsa/anaconda3/envs/py37/lib/python3.7/site-packages/IPython/core/ultratb.py\", line 1170, in get_records\n",
      "    return _fixed_getinnerframes(etb, number_of_lines_of_context, tb_offset)\n",
      "  File \"/home/utsa/anaconda3/envs/py37/lib/python3.7/site-packages/IPython/core/ultratb.py\", line 316, in wrapped\n",
      "    return f(*args, **kwargs)\n",
      "  File \"/home/utsa/anaconda3/envs/py37/lib/python3.7/site-packages/IPython/core/ultratb.py\", line 350, in _fixed_getinnerframes\n",
      "    records = fix_frame_records_filenames(inspect.getinnerframes(etb, context))\n",
      "  File \"/home/utsa/anaconda3/envs/py37/lib/python3.7/inspect.py\", line 1502, in getinnerframes\n",
      "    frameinfo = (tb.tb_frame,) + getframeinfo(tb, context)\n",
      "  File \"/home/utsa/anaconda3/envs/py37/lib/python3.7/inspect.py\", line 1460, in getframeinfo\n",
      "    filename = getsourcefile(frame) or getfile(frame)\n",
      "  File \"/home/utsa/anaconda3/envs/py37/lib/python3.7/inspect.py\", line 696, in getsourcefile\n",
      "    if getattr(getmodule(object, filename), '__loader__', None) is not None:\n",
      "  File \"/home/utsa/anaconda3/envs/py37/lib/python3.7/inspect.py\", line 725, in getmodule\n",
      "    file = getabsfile(object, _filename)\n",
      "  File \"/home/utsa/anaconda3/envs/py37/lib/python3.7/inspect.py\", line 709, in getabsfile\n",
      "    return os.path.normcase(os.path.abspath(_filename))\n",
      "  File \"/home/utsa/anaconda3/envs/py37/lib/python3.7/posixpath.py\", line 383, in abspath\n",
      "    cwd = os.getcwd()\n",
      "FileNotFoundError: [Errno 2] No such file or directory\n",
      "Traceback (most recent call last):\n",
      "  File \"/home/utsa/anaconda3/envs/py37/lib/python3.7/site-packages/IPython/core/interactiveshell.py\", line 3418, in run_code\n",
      "    exec(code_obj, self.user_global_ns, self.user_ns)\n",
      "  File \"<ipython-input-261-55ddc41a7a3a>\", line 1, in <module>\n",
      "    precoders, labels = load_dataset('datasets', fading, ant, SNR, bit)\n",
      "  File \"<ipython-input-255-529c16c6c308>\", line 4, in load_dataset\n",
      "    os.makedirs(dir_name)\n",
      "  File \"/home/utsa/anaconda3/envs/py37/lib/python3.7/os.py\", line 223, in makedirs\n",
      "    mkdir(name, mode)\n",
      "FileNotFoundError: [Errno 2] No such file or directory: 'datasets'\n",
      "\n",
      "During handling of the above exception, another exception occurred:\n",
      "\n",
      "Traceback (most recent call last):\n",
      "  File \"/home/utsa/anaconda3/envs/py37/lib/python3.7/site-packages/IPython/core/interactiveshell.py\", line 2045, in showtraceback\n",
      "    stb = value._render_traceback_()\n",
      "AttributeError: 'FileNotFoundError' object has no attribute '_render_traceback_'\n",
      "\n",
      "During handling of the above exception, another exception occurred:\n",
      "\n",
      "Traceback (most recent call last):\n",
      "  File \"/home/utsa/anaconda3/envs/py37/lib/python3.7/site-packages/IPython/core/interactiveshell.py\", line 3338, in run_ast_nodes\n",
      "    if (await self.run_code(code, result,  async_=asy)):\n",
      "  File \"/home/utsa/anaconda3/envs/py37/lib/python3.7/site-packages/IPython/core/interactiveshell.py\", line 3435, in run_code\n",
      "    self.showtraceback(running_compiled_code=True)\n",
      "  File \"/home/utsa/anaconda3/envs/py37/lib/python3.7/site-packages/IPython/core/interactiveshell.py\", line 2048, in showtraceback\n",
      "    value, tb, tb_offset=tb_offset)\n",
      "  File \"/home/utsa/anaconda3/envs/py37/lib/python3.7/site-packages/IPython/core/ultratb.py\", line 1437, in structured_traceback\n",
      "    self, etype, value, tb, tb_offset, number_of_lines_of_context)\n",
      "  File \"/home/utsa/anaconda3/envs/py37/lib/python3.7/site-packages/IPython/core/ultratb.py\", line 1337, in structured_traceback\n",
      "    self, etype, value, tb, tb_offset, number_of_lines_of_context\n",
      "  File \"/home/utsa/anaconda3/envs/py37/lib/python3.7/site-packages/IPython/core/ultratb.py\", line 1194, in structured_traceback\n",
      "    tb_offset)\n",
      "  File \"/home/utsa/anaconda3/envs/py37/lib/python3.7/site-packages/IPython/core/ultratb.py\", line 1151, in format_exception_as_a_whole\n",
      "    last_unique, recursion_repeat = find_recursion(orig_etype, evalue, records)\n",
      "  File \"/home/utsa/anaconda3/envs/py37/lib/python3.7/site-packages/IPython/core/ultratb.py\", line 451, in find_recursion\n",
      "    return len(records), 0\n",
      "TypeError: object of type 'NoneType' has no len()\n",
      "\n",
      "During handling of the above exception, another exception occurred:\n",
      "\n",
      "Traceback (most recent call last):\n",
      "  File \"/home/utsa/anaconda3/envs/py37/lib/python3.7/site-packages/IPython/core/interactiveshell.py\", line 2045, in showtraceback\n",
      "    stb = value._render_traceback_()\n",
      "AttributeError: 'TypeError' object has no attribute '_render_traceback_'\n",
      "\n",
      "During handling of the above exception, another exception occurred:\n",
      "\n",
      "Traceback (most recent call last):\n",
      "  File \"/home/utsa/anaconda3/envs/py37/lib/python3.7/site-packages/IPython/core/interactiveshell.py\", line 2923, in _run_cell\n",
      "    return runner(coro)\n",
      "  File \"/home/utsa/anaconda3/envs/py37/lib/python3.7/site-packages/IPython/core/async_helpers.py\", line 68, in _pseudo_sync_runner\n",
      "    coro.send(None)\n",
      "  File \"/home/utsa/anaconda3/envs/py37/lib/python3.7/site-packages/IPython/core/interactiveshell.py\", line 3147, in run_cell_async\n",
      "    interactivity=interactivity, compiler=compiler, result=result)\n",
      "  File \"/home/utsa/anaconda3/envs/py37/lib/python3.7/site-packages/IPython/core/interactiveshell.py\", line 3357, in run_ast_nodes\n",
      "    self.showtraceback()\n",
      "  File \"/home/utsa/anaconda3/envs/py37/lib/python3.7/site-packages/IPython/core/interactiveshell.py\", line 2048, in showtraceback\n",
      "    value, tb, tb_offset=tb_offset)\n",
      "  File \"/home/utsa/anaconda3/envs/py37/lib/python3.7/site-packages/IPython/core/ultratb.py\", line 1437, in structured_traceback\n",
      "    self, etype, value, tb, tb_offset, number_of_lines_of_context)\n",
      "  File \"/home/utsa/anaconda3/envs/py37/lib/python3.7/site-packages/IPython/core/ultratb.py\", line 1337, in structured_traceback\n",
      "    self, etype, value, tb, tb_offset, number_of_lines_of_context\n",
      "  File \"/home/utsa/anaconda3/envs/py37/lib/python3.7/site-packages/IPython/core/ultratb.py\", line 1212, in structured_traceback\n",
      "    chained_exceptions_tb_offset)\n",
      "  File \"/home/utsa/anaconda3/envs/py37/lib/python3.7/site-packages/IPython/core/ultratb.py\", line 1151, in format_exception_as_a_whole\n",
      "    last_unique, recursion_repeat = find_recursion(orig_etype, evalue, records)\n",
      "  File \"/home/utsa/anaconda3/envs/py37/lib/python3.7/site-packages/IPython/core/ultratb.py\", line 451, in find_recursion\n",
      "    return len(records), 0\n",
      "TypeError: object of type 'NoneType' has no len()\n",
      "\n",
      "During handling of the above exception, another exception occurred:\n",
      "\n",
      "Traceback (most recent call last):\n",
      "  File \"/home/utsa/anaconda3/envs/py37/lib/python3.7/site-packages/IPython/core/interactiveshell.py\", line 2045, in showtraceback\n",
      "    stb = value._render_traceback_()\n",
      "AttributeError: 'TypeError' object has no attribute '_render_traceback_'\n",
      "\n",
      "During handling of the above exception, another exception occurred:\n",
      "\n",
      "Traceback (most recent call last):\n",
      "  File \"/home/utsa/anaconda3/envs/py37/lib/python3.7/site-packages/IPython/core/ultratb.py\", line 1170, in get_records\n",
      "    return _fixed_getinnerframes(etb, number_of_lines_of_context, tb_offset)\n",
      "  File \"/home/utsa/anaconda3/envs/py37/lib/python3.7/site-packages/IPython/core/ultratb.py\", line 316, in wrapped\n",
      "    return f(*args, **kwargs)\n",
      "  File \"/home/utsa/anaconda3/envs/py37/lib/python3.7/site-packages/IPython/core/ultratb.py\", line 350, in _fixed_getinnerframes\n",
      "    records = fix_frame_records_filenames(inspect.getinnerframes(etb, context))\n",
      "  File \"/home/utsa/anaconda3/envs/py37/lib/python3.7/inspect.py\", line 1502, in getinnerframes\n",
      "    frameinfo = (tb.tb_frame,) + getframeinfo(tb, context)\n",
      "  File \"/home/utsa/anaconda3/envs/py37/lib/python3.7/inspect.py\", line 1460, in getframeinfo\n",
      "    filename = getsourcefile(frame) or getfile(frame)\n",
      "  File \"/home/utsa/anaconda3/envs/py37/lib/python3.7/inspect.py\", line 696, in getsourcefile\n",
      "    if getattr(getmodule(object, filename), '__loader__', None) is not None:\n",
      "  File \"/home/utsa/anaconda3/envs/py37/lib/python3.7/inspect.py\", line 725, in getmodule\n",
      "    file = getabsfile(object, _filename)\n",
      "  File \"/home/utsa/anaconda3/envs/py37/lib/python3.7/inspect.py\", line 709, in getabsfile\n",
      "    return os.path.normcase(os.path.abspath(_filename))\n",
      "  File \"/home/utsa/anaconda3/envs/py37/lib/python3.7/posixpath.py\", line 383, in abspath\n",
      "    cwd = os.getcwd()\n",
      "FileNotFoundError: [Errno 2] No such file or directory\n"
     ]
    }
   ],
   "source": [
    "precoders, labels = load_dataset('datasets', fading, ant, SNR, bit)\n",
    "if visual == 1:\n",
    "    visualize(precoders)\n",
    "\n",
    "precoder_data = stack(precoders, axis=0)\n",
    "precoder_labels = array(labels)\n",
    "\n",
    "precoder_dataset = PrecoderDataset(precoder_data, precoder_labels)\n",
    "train, val = random_split(precoder_dataset, [int(0.8*max_iter), int(0.2*max_iter)])\n",
    "train_loader = DataLoader(train, batch_size=128, shuffle=True, num_workers=0)\n",
    "val_loader = DataLoader(val, batch_size=128, shuffle=True, num_workers=0)\n",
    "\n",
    "num_classes = 2**bit\n",
    "nn_input_size = 2*ant*ant\n",
    "nn_output_size = num_classes\n",
    "\n",
    "model = Model(nn_input_size, nn_output_size)\n",
    "\n",
    "if torch.cuda.is_available():\n",
    "    model.cuda()\n",
    "\n",
    "optimizer = optim.SGD(model.parameters(), lr=learning_rate)\n",
    "# optimizer = optim.Adam(model.parameters(), lr=learning_rate)\n",
    "loss = nn.CrossEntropyLoss()\n",
    "for epoch in range(num_epochs):\n",
    "\n",
    "    # TRAINING\n",
    "    model.train()\n",
    "    training_total_correct = 0\n",
    "    training_losses = list()\n",
    "    for batch in train_loader:\n",
    "\n",
    "        x, y = batch # extracted from the batch\n",
    "\n",
    "        if torch.cuda.is_available():\n",
    "            x = x.cuda()\n",
    "            y = y.cuda()\n",
    "\n",
    "        # step 1: forward pass\n",
    "        prob = model(x)\n",
    "\n",
    "        output = prob\n",
    "        target = y\n",
    "\n",
    "        # step 2: compute objective function - measuring distance between the output of the network vs actual answer\n",
    "        obj_func = loss(output, target)\n",
    "\n",
    "        # step 3: clear the gradients\n",
    "        model.zero_grad()\n",
    "\n",
    "        # step 4: accumulate partial derivatives of obj_func wrt parameters\n",
    "        obj_func.backward()\n",
    "\n",
    "        # step 5: step in the opposite direction of the gradient\n",
    "        optimizer.step()\n",
    "\n",
    "        training_losses.append(obj_func.item())\n",
    "\n",
    "        max_prob, max_ind = torch.max(output, 1)\n",
    "        for ind in range(len(max_ind)):\n",
    "            if torch.equal(max_ind[ind], y[ind]):\n",
    "                training_total_correct += 1\n",
    "\n",
    "    # VALIDATION\n",
    "    model.eval()\n",
    "\n",
    "    validation_total_correct = 0\n",
    "    validation_losses = list()\n",
    "    for batch in val_loader:\n",
    "\n",
    "        x, y = batch # extracted from the batch\n",
    "\n",
    "        if torch.cuda.is_available():\n",
    "            x = x.cuda()\n",
    "            y = y.cuda()\n",
    "\n",
    "        # step 1: forward pass\n",
    "        with torch.no_grad():\n",
    "            prob = model(x)\n",
    "\n",
    "        output = prob\n",
    "        target = y\n",
    "\n",
    "        # step 2: compute objective function - measuring distance between the output of the network vs actual answer\n",
    "        obj_func = loss(output, target)\n",
    "        validation_losses.append(obj_func.item())\n",
    "\n",
    "        max_prob, max_ind = torch.max(output, 1)\n",
    "\n",
    "        for ind in range(len(max_ind)):\n",
    "            if torch.equal(max_ind[ind], y[ind]):\n",
    "                validation_total_correct += 1\n",
    "    training_accuracy = (training_total_correct/len(train))*100\n",
    "    validation_accuracy = (validation_total_correct/len(val))*100\n",
    "\n",
    "    print(f'Epoch {epoch + 1}, training loss: {torch.tensor(training_losses).mean():.8f}, training accuracy: {training_accuracy}%, validation loss: {torch.tensor(validation_losses).mean():.8f}, validation accuracy: {validation_accuracy[snr_loop, ant_loop, bit_loop, epoch]}%')\n"
   ]
  },
  {
   "cell_type": "markdown",
   "metadata": {},
   "source": [
    "## Dump validation results"
   ]
  },
  {
   "cell_type": "code",
   "execution_count": null,
   "metadata": {
    "collapsed": false,
    "jupyter": {
     "outputs_hidden": false
    },
    "pycharm": {
     "name": "#%%\n"
    }
   },
   "outputs": [
    {
     "name": "stderr",
     "output_type": "stream",
     "text": [
      "ERROR:root:Internal Python error in the inspect module.\n",
      "Below is the traceback from this internal error.\n",
      "\n",
      "ERROR:root:Internal Python error in the inspect module.\n",
      "Below is the traceback from this internal error.\n",
      "\n",
      "ERROR:root:Internal Python error in the inspect module.\n",
      "Below is the traceback from this internal error.\n",
      "\n"
     ]
    },
    {
     "name": "stdout",
     "output_type": "stream",
     "text": [
      "Traceback (most recent call last):\n",
      "  File \"/home/utsa/anaconda3/envs/py37/lib/python3.7/site-packages/IPython/core/interactiveshell.py\", line 3418, in run_code\n",
      "    exec(code_obj, self.user_global_ns, self.user_ns)\n",
      "  File \"<ipython-input-261-24de0b76e7fe>\", line 4, in <module>\n",
      "    acc_pkl_file = open(acc_pkl, 'wb')\n",
      "FileNotFoundError: [Errno 2] No such file or directory: 'validation_accuracy.pkl'\n",
      "\n",
      "During handling of the above exception, another exception occurred:\n",
      "\n",
      "Traceback (most recent call last):\n",
      "  File \"/home/utsa/anaconda3/envs/py37/lib/python3.7/site-packages/IPython/core/interactiveshell.py\", line 2045, in showtraceback\n",
      "    stb = value._render_traceback_()\n",
      "AttributeError: 'FileNotFoundError' object has no attribute '_render_traceback_'\n",
      "\n",
      "During handling of the above exception, another exception occurred:\n",
      "\n",
      "Traceback (most recent call last):\n",
      "  File \"/home/utsa/anaconda3/envs/py37/lib/python3.7/site-packages/IPython/core/ultratb.py\", line 1170, in get_records\n",
      "    return _fixed_getinnerframes(etb, number_of_lines_of_context, tb_offset)\n",
      "  File \"/home/utsa/anaconda3/envs/py37/lib/python3.7/site-packages/IPython/core/ultratb.py\", line 316, in wrapped\n",
      "    return f(*args, **kwargs)\n",
      "  File \"/home/utsa/anaconda3/envs/py37/lib/python3.7/site-packages/IPython/core/ultratb.py\", line 350, in _fixed_getinnerframes\n",
      "    records = fix_frame_records_filenames(inspect.getinnerframes(etb, context))\n",
      "  File \"/home/utsa/anaconda3/envs/py37/lib/python3.7/inspect.py\", line 1502, in getinnerframes\n",
      "    frameinfo = (tb.tb_frame,) + getframeinfo(tb, context)\n",
      "  File \"/home/utsa/anaconda3/envs/py37/lib/python3.7/inspect.py\", line 1460, in getframeinfo\n",
      "    filename = getsourcefile(frame) or getfile(frame)\n",
      "  File \"/home/utsa/anaconda3/envs/py37/lib/python3.7/inspect.py\", line 696, in getsourcefile\n",
      "    if getattr(getmodule(object, filename), '__loader__', None) is not None:\n",
      "  File \"/home/utsa/anaconda3/envs/py37/lib/python3.7/inspect.py\", line 725, in getmodule\n",
      "    file = getabsfile(object, _filename)\n",
      "  File \"/home/utsa/anaconda3/envs/py37/lib/python3.7/inspect.py\", line 709, in getabsfile\n",
      "    return os.path.normcase(os.path.abspath(_filename))\n",
      "  File \"/home/utsa/anaconda3/envs/py37/lib/python3.7/posixpath.py\", line 383, in abspath\n",
      "    cwd = os.getcwd()\n",
      "FileNotFoundError: [Errno 2] No such file or directory\n",
      "ERROR! Session/line number was not unique in database. History logging moved to new session 149\n",
      "Traceback (most recent call last):\n",
      "  File \"/home/utsa/anaconda3/envs/py37/lib/python3.7/site-packages/IPython/core/interactiveshell.py\", line 3418, in run_code\n",
      "    exec(code_obj, self.user_global_ns, self.user_ns)\n",
      "  File \"<ipython-input-261-24de0b76e7fe>\", line 4, in <module>\n",
      "    acc_pkl_file = open(acc_pkl, 'wb')\n",
      "FileNotFoundError: [Errno 2] No such file or directory: 'validation_accuracy.pkl'\n",
      "\n",
      "During handling of the above exception, another exception occurred:\n",
      "\n",
      "Traceback (most recent call last):\n",
      "  File \"/home/utsa/anaconda3/envs/py37/lib/python3.7/site-packages/IPython/core/interactiveshell.py\", line 2045, in showtraceback\n",
      "    stb = value._render_traceback_()\n",
      "AttributeError: 'FileNotFoundError' object has no attribute '_render_traceback_'\n",
      "\n",
      "During handling of the above exception, another exception occurred:\n",
      "\n",
      "Traceback (most recent call last):\n",
      "  File \"/home/utsa/anaconda3/envs/py37/lib/python3.7/site-packages/IPython/core/interactiveshell.py\", line 3338, in run_ast_nodes\n",
      "    if (await self.run_code(code, result,  async_=asy)):\n",
      "  File \"/home/utsa/anaconda3/envs/py37/lib/python3.7/site-packages/IPython/core/interactiveshell.py\", line 3435, in run_code\n",
      "    self.showtraceback(running_compiled_code=True)\n",
      "  File \"/home/utsa/anaconda3/envs/py37/lib/python3.7/site-packages/IPython/core/interactiveshell.py\", line 2048, in showtraceback\n",
      "    value, tb, tb_offset=tb_offset)\n",
      "  File \"/home/utsa/anaconda3/envs/py37/lib/python3.7/site-packages/IPython/core/ultratb.py\", line 1437, in structured_traceback\n",
      "    self, etype, value, tb, tb_offset, number_of_lines_of_context)\n",
      "  File \"/home/utsa/anaconda3/envs/py37/lib/python3.7/site-packages/IPython/core/ultratb.py\", line 1337, in structured_traceback\n",
      "    self, etype, value, tb, tb_offset, number_of_lines_of_context\n",
      "  File \"/home/utsa/anaconda3/envs/py37/lib/python3.7/site-packages/IPython/core/ultratb.py\", line 1194, in structured_traceback\n",
      "    tb_offset)\n",
      "  File \"/home/utsa/anaconda3/envs/py37/lib/python3.7/site-packages/IPython/core/ultratb.py\", line 1151, in format_exception_as_a_whole\n",
      "    last_unique, recursion_repeat = find_recursion(orig_etype, evalue, records)\n",
      "  File \"/home/utsa/anaconda3/envs/py37/lib/python3.7/site-packages/IPython/core/ultratb.py\", line 451, in find_recursion\n",
      "    return len(records), 0\n",
      "TypeError: object of type 'NoneType' has no len()\n",
      "\n",
      "During handling of the above exception, another exception occurred:\n",
      "\n",
      "Traceback (most recent call last):\n",
      "  File \"/home/utsa/anaconda3/envs/py37/lib/python3.7/site-packages/IPython/core/interactiveshell.py\", line 2045, in showtraceback\n",
      "    stb = value._render_traceback_()\n",
      "AttributeError: 'TypeError' object has no attribute '_render_traceback_'\n",
      "\n",
      "During handling of the above exception, another exception occurred:\n",
      "\n",
      "Traceback (most recent call last):\n",
      "  File \"/home/utsa/anaconda3/envs/py37/lib/python3.7/site-packages/IPython/core/ultratb.py\", line 1170, in get_records\n",
      "    return _fixed_getinnerframes(etb, number_of_lines_of_context, tb_offset)\n",
      "  File \"/home/utsa/anaconda3/envs/py37/lib/python3.7/site-packages/IPython/core/ultratb.py\", line 316, in wrapped\n",
      "    return f(*args, **kwargs)\n",
      "  File \"/home/utsa/anaconda3/envs/py37/lib/python3.7/site-packages/IPython/core/ultratb.py\", line 350, in _fixed_getinnerframes\n",
      "    records = fix_frame_records_filenames(inspect.getinnerframes(etb, context))\n",
      "  File \"/home/utsa/anaconda3/envs/py37/lib/python3.7/inspect.py\", line 1502, in getinnerframes\n",
      "    frameinfo = (tb.tb_frame,) + getframeinfo(tb, context)\n",
      "  File \"/home/utsa/anaconda3/envs/py37/lib/python3.7/inspect.py\", line 1460, in getframeinfo\n",
      "    filename = getsourcefile(frame) or getfile(frame)\n",
      "  File \"/home/utsa/anaconda3/envs/py37/lib/python3.7/inspect.py\", line 696, in getsourcefile\n",
      "    if getattr(getmodule(object, filename), '__loader__', None) is not None:\n",
      "  File \"/home/utsa/anaconda3/envs/py37/lib/python3.7/inspect.py\", line 725, in getmodule\n",
      "    file = getabsfile(object, _filename)\n",
      "  File \"/home/utsa/anaconda3/envs/py37/lib/python3.7/inspect.py\", line 709, in getabsfile\n",
      "    return os.path.normcase(os.path.abspath(_filename))\n",
      "  File \"/home/utsa/anaconda3/envs/py37/lib/python3.7/posixpath.py\", line 383, in abspath\n",
      "    cwd = os.getcwd()\n",
      "FileNotFoundError: [Errno 2] No such file or directory\n",
      "Traceback (most recent call last):\n",
      "  File \"/home/utsa/anaconda3/envs/py37/lib/python3.7/site-packages/IPython/core/interactiveshell.py\", line 3418, in run_code\n",
      "    exec(code_obj, self.user_global_ns, self.user_ns)\n",
      "  File \"<ipython-input-261-24de0b76e7fe>\", line 4, in <module>\n",
      "    acc_pkl_file = open(acc_pkl, 'wb')\n",
      "FileNotFoundError: [Errno 2] No such file or directory: 'validation_accuracy.pkl'\n",
      "\n",
      "During handling of the above exception, another exception occurred:\n",
      "\n",
      "Traceback (most recent call last):\n",
      "  File \"/home/utsa/anaconda3/envs/py37/lib/python3.7/site-packages/IPython/core/interactiveshell.py\", line 2045, in showtraceback\n",
      "    stb = value._render_traceback_()\n",
      "AttributeError: 'FileNotFoundError' object has no attribute '_render_traceback_'\n",
      "\n",
      "During handling of the above exception, another exception occurred:\n",
      "\n",
      "Traceback (most recent call last):\n",
      "  File \"/home/utsa/anaconda3/envs/py37/lib/python3.7/site-packages/IPython/core/interactiveshell.py\", line 3338, in run_ast_nodes\n",
      "    if (await self.run_code(code, result,  async_=asy)):\n",
      "  File \"/home/utsa/anaconda3/envs/py37/lib/python3.7/site-packages/IPython/core/interactiveshell.py\", line 3435, in run_code\n",
      "    self.showtraceback(running_compiled_code=True)\n",
      "  File \"/home/utsa/anaconda3/envs/py37/lib/python3.7/site-packages/IPython/core/interactiveshell.py\", line 2048, in showtraceback\n",
      "    value, tb, tb_offset=tb_offset)\n",
      "  File \"/home/utsa/anaconda3/envs/py37/lib/python3.7/site-packages/IPython/core/ultratb.py\", line 1437, in structured_traceback\n",
      "    self, etype, value, tb, tb_offset, number_of_lines_of_context)\n",
      "  File \"/home/utsa/anaconda3/envs/py37/lib/python3.7/site-packages/IPython/core/ultratb.py\", line 1337, in structured_traceback\n",
      "    self, etype, value, tb, tb_offset, number_of_lines_of_context\n",
      "  File \"/home/utsa/anaconda3/envs/py37/lib/python3.7/site-packages/IPython/core/ultratb.py\", line 1194, in structured_traceback\n",
      "    tb_offset)\n",
      "  File \"/home/utsa/anaconda3/envs/py37/lib/python3.7/site-packages/IPython/core/ultratb.py\", line 1151, in format_exception_as_a_whole\n",
      "    last_unique, recursion_repeat = find_recursion(orig_etype, evalue, records)\n",
      "  File \"/home/utsa/anaconda3/envs/py37/lib/python3.7/site-packages/IPython/core/ultratb.py\", line 451, in find_recursion\n",
      "    return len(records), 0\n",
      "TypeError: object of type 'NoneType' has no len()\n",
      "\n",
      "During handling of the above exception, another exception occurred:\n",
      "\n",
      "Traceback (most recent call last):\n",
      "  File \"/home/utsa/anaconda3/envs/py37/lib/python3.7/site-packages/IPython/core/interactiveshell.py\", line 2045, in showtraceback\n",
      "    stb = value._render_traceback_()\n",
      "AttributeError: 'TypeError' object has no attribute '_render_traceback_'\n",
      "\n",
      "During handling of the above exception, another exception occurred:\n",
      "\n",
      "Traceback (most recent call last):\n",
      "  File \"/home/utsa/anaconda3/envs/py37/lib/python3.7/site-packages/IPython/core/interactiveshell.py\", line 2923, in _run_cell\n",
      "    return runner(coro)\n",
      "  File \"/home/utsa/anaconda3/envs/py37/lib/python3.7/site-packages/IPython/core/async_helpers.py\", line 68, in _pseudo_sync_runner\n",
      "    coro.send(None)\n",
      "  File \"/home/utsa/anaconda3/envs/py37/lib/python3.7/site-packages/IPython/core/interactiveshell.py\", line 3147, in run_cell_async\n",
      "    interactivity=interactivity, compiler=compiler, result=result)\n",
      "  File \"/home/utsa/anaconda3/envs/py37/lib/python3.7/site-packages/IPython/core/interactiveshell.py\", line 3357, in run_ast_nodes\n",
      "    self.showtraceback()\n",
      "  File \"/home/utsa/anaconda3/envs/py37/lib/python3.7/site-packages/IPython/core/interactiveshell.py\", line 2048, in showtraceback\n",
      "    value, tb, tb_offset=tb_offset)\n",
      "  File \"/home/utsa/anaconda3/envs/py37/lib/python3.7/site-packages/IPython/core/ultratb.py\", line 1437, in structured_traceback\n",
      "    self, etype, value, tb, tb_offset, number_of_lines_of_context)\n",
      "  File \"/home/utsa/anaconda3/envs/py37/lib/python3.7/site-packages/IPython/core/ultratb.py\", line 1337, in structured_traceback\n",
      "    self, etype, value, tb, tb_offset, number_of_lines_of_context\n",
      "  File \"/home/utsa/anaconda3/envs/py37/lib/python3.7/site-packages/IPython/core/ultratb.py\", line 1212, in structured_traceback\n",
      "    chained_exceptions_tb_offset)\n",
      "  File \"/home/utsa/anaconda3/envs/py37/lib/python3.7/site-packages/IPython/core/ultratb.py\", line 1151, in format_exception_as_a_whole\n",
      "    last_unique, recursion_repeat = find_recursion(orig_etype, evalue, records)\n",
      "  File \"/home/utsa/anaconda3/envs/py37/lib/python3.7/site-packages/IPython/core/ultratb.py\", line 451, in find_recursion\n",
      "    return len(records), 0\n",
      "TypeError: object of type 'NoneType' has no len()\n",
      "\n",
      "During handling of the above exception, another exception occurred:\n",
      "\n",
      "Traceback (most recent call last):\n",
      "  File \"/home/utsa/anaconda3/envs/py37/lib/python3.7/site-packages/IPython/core/interactiveshell.py\", line 2045, in showtraceback\n",
      "    stb = value._render_traceback_()\n",
      "AttributeError: 'TypeError' object has no attribute '_render_traceback_'\n",
      "\n",
      "During handling of the above exception, another exception occurred:\n",
      "\n",
      "Traceback (most recent call last):\n",
      "  File \"/home/utsa/anaconda3/envs/py37/lib/python3.7/site-packages/IPython/core/ultratb.py\", line 1170, in get_records\n",
      "    return _fixed_getinnerframes(etb, number_of_lines_of_context, tb_offset)\n",
      "  File \"/home/utsa/anaconda3/envs/py37/lib/python3.7/site-packages/IPython/core/ultratb.py\", line 316, in wrapped\n",
      "    return f(*args, **kwargs)\n",
      "  File \"/home/utsa/anaconda3/envs/py37/lib/python3.7/site-packages/IPython/core/ultratb.py\", line 350, in _fixed_getinnerframes\n",
      "    records = fix_frame_records_filenames(inspect.getinnerframes(etb, context))\n",
      "  File \"/home/utsa/anaconda3/envs/py37/lib/python3.7/inspect.py\", line 1502, in getinnerframes\n",
      "    frameinfo = (tb.tb_frame,) + getframeinfo(tb, context)\n",
      "  File \"/home/utsa/anaconda3/envs/py37/lib/python3.7/inspect.py\", line 1460, in getframeinfo\n",
      "    filename = getsourcefile(frame) or getfile(frame)\n",
      "  File \"/home/utsa/anaconda3/envs/py37/lib/python3.7/inspect.py\", line 696, in getsourcefile\n",
      "    if getattr(getmodule(object, filename), '__loader__', None) is not None:\n",
      "  File \"/home/utsa/anaconda3/envs/py37/lib/python3.7/inspect.py\", line 725, in getmodule\n",
      "    file = getabsfile(object, _filename)\n",
      "  File \"/home/utsa/anaconda3/envs/py37/lib/python3.7/inspect.py\", line 709, in getabsfile\n",
      "    return os.path.normcase(os.path.abspath(_filename))\n",
      "  File \"/home/utsa/anaconda3/envs/py37/lib/python3.7/posixpath.py\", line 383, in abspath\n",
      "    cwd = os.getcwd()\n",
      "FileNotFoundError: [Errno 2] No such file or directory\n"
     ]
    }
   ],
   "source": [
    "acc_pkl = 'validation_accuracy.pkl'\n",
    "loss_pkl = 'validation_loss.pkl'\n",
    "\n",
    "acc_pkl_file = open(acc_pkl, 'wb')\n",
    "loss_pkl_file = open(loss_pkl, 'wb')\n",
    "\n",
    "dump(validation_accuracy, acc_pkl_file)\n",
    "dump(validation_loss_buffer, loss_pkl_file)\n",
    "\n",
    "acc_pkl_file.close()\n",
    "loss_pkl_file.close()\n"
   ]
  }
 ],
 "metadata": {
  "kernelspec": {
   "display_name": "Python 3",
   "language": "python",
   "name": "python3"
  },
  "language_info": {
   "codemirror_mode": {
    "name": "ipython",
    "version": 3
   },
   "file_extension": ".py",
   "mimetype": "text/x-python",
   "name": "python",
   "nbconvert_exporter": "python",
   "pygments_lexer": "ipython3",
   "version": "3.7.9"
  }
 },
 "nbformat": 4,
 "nbformat_minor": 4
}
